<?xml version="1.0"?>
<robot xmlns:xacro="http://ros.org/wiki/xacro">
  <xacro:macro name="wheel_steering" params="side pos_x pos_y pos_z mass parent_link max_steer">
    <link name="${side}_wheel_steering_link">
      <collision>
        <origin xyz="0 0 0" rpy="0 0 0"/>
        <geometry>
          <cylinder radius="0.02" length="0.02"/>
        </geometry>
      </collision>

      <inertial>
        <origin xyz="0 0 0" rpy="0 0 0"/>
        <mass value="1"/>
        <inertia ixx="1.0" ixy="0" ixz="0"
                 iyy="1.0" iyz="0"
                 izz="1.0" />
      </inertial>
    </link>
    <gazebo reference="${side}_wheel_steering_link">  
      <visual>  
        <material>
          <ambient>0.1764 0.4588 0.8509 1.0</ambient>  
          <diffuse>0.1764 0.4588 0.8509 1.0</diffuse>  
          <specular>0.1764 0.4588 0.8509 1.0</specular>  
          <emissive>0.0 0.0 0.0 0.0</emissive>  
        </material>
      </visual>  
    </gazebo>
    <joint name="${side}_wheel_steering_joint" type="revolute">
      <axis xyz="0 0 1" />
      <parent link="${parent_link}"/>
      <child link="${side}_wheel_steering_link"/>
      <origin xyz="${pos_x} ${pos_y} ${pos_z}" rpy="0 0 0"/>
      <limit lower="${-max_steer}" upper="${max_steer}" velocity="1.0" effort="25.0"/>
    </joint>
    <gazebo reference="${side}_wheel_steering_joint">
    </gazebo>  

  </xacro:macro>
</robot>